Workbook
Name Segment_Gender_Value: #N/A
Name Segment_Order_Mode: #N/A

Sheet Data
A1: TX ID | B1: Product | C1: Quantity | D1: Unit Price | E1: Amount | F1: Order Date | G1: Ship Date | H1: Customer Gender | I1: Order Mode | J1: Rating C | K1: State | L1: County | M1: Days to Deliver | N1: Weeknum | O1: Gender Value
A2: TX500001 | B2: Shorts | C2: 1 | D2: 10.9 | E2: 10.9 | F2: 45658 | G2: 45663 | I2: App | J2: 4 | K2: California | L2: Alpine County | M2: =orders[[#This Row],[Ship Date]]-orders[[#This Row],[Order Date]] -> 5 | N2: =WEEKNUM(orders[[#This Row],[Order Date]]) -> 1 | O2: =IF(orders[[#This Row],[Customer Gender]]="M","Male",IF( orders[[#This Row],[Customer Gender]]="F","Female",IF( orders[[#This Row],[Customer Gender]]="O","Other", "Unknown"))) -> Unknown
A3: TX500002 | B3: Tank Tops | C3: 2 | D3: 30.6 | E3: 61.2 | F3: 45658 | G3: 45660 | H3: M | I3: App | J3: 4 | K3: California | L3: Contra Costa County | M3: =orders[[#This Row],[Ship Date]]-orders[[#This Row],[Order Date]] -> 2 | N3: =WEEKNUM(orders[[#This Row],[Order Date]]) -> 1 | O3: =IF(orders[[#This Row],[Customer Gender]]="M","Male",IF( orders[[#This Row],[Customer Gender]]="F","Female",IF( orders[[#This Row],[Customer Gender]]="O","Other", "Unknown"))) -> Male
A4: TX500003 | B4: Sneakers | C4: 3 | D4: 109.4 | E4: 328.2 | F4: 45658 | G4: 45661 | H4: F | I4: App | J4: 3 | K4: California | L4: Fresno County | M4: =orders[[#This Row],[Ship Date]]-orders[[#This Row],[Order Date]] -> 3 | N4: =WEEKNUM(orders[[#This Row],[Order Date]]) -> 1 | O4: =IF(orders[[#This Row],[Customer Gender]]="M","Male",IF( orders[[#This Row],[Customer Gender]]="F","Female",IF( orders[[#This Row],[Customer Gender]]="O","Other", "Unknown"))) -> Female
A5: TX500004 | B5: Workout Tops | C5: 7 | D5: 37.7 | E5: 263.9 | F5: 45658 | G5: 45659 | H5: F | I5: App | J5: 4 | K5: California | L5: Fresno County | M5: =orders[[#This Row],[Ship Date]]-orders[[#This Row],[Order Date]] -> 1 | N5: =WEEKNUM(orders[[#This Row],[Order Date]]) -> 1 | O5: =IF(orders[[#This Row],[Customer Gender]]="M","Male",IF( orders[[#This Row],[Customer Gender]]="F","Female",IF( orders[[#This Row],[Customer Gender]]="O","Other", "Unknown"))) -> Female
A6: TX500005 | B6: Graphic Tees | C6: 3 | D6: 56.7 | E6: 170.1 | F6: 45658 | G6: 45661 | H6: F | I6: App | J6: 5 | K6: California | L6: Los Angeles County | M6: =orders[[#This Row],[Ship Date]]-orders[[#This Row],[Order Date]] -> 3 | N6: =WEEKNUM(orders[[#This Row],[Order Date]]) -> 1 | O6: =IF(orders[[#This Row],[Customer Gender]]="M","Male",IF( orders[[#This Row],[Customer Gender]]="F","Female",IF( orders[[#This Row],[Customer Gender]]="O","Other", "Unknown"))) -> Female
A7: TX500006 | B7: Tank Tops | C7: 12 | D7: 83.5 | E7: 1002 | F7: 45658 | G7: 45661 | H7: M | I7: Website | J7: 4 | K7: California | L7: Los Angeles County | M7: =orders[[#This Row],[Ship Date]]-orders[[#This Row],[Order Date]] -> 3 | N7: =WEEKNUM(orders[[#This Row],[Order Date]]) -> 1 | O7: =IF(orders[[#This Row],[Customer Gender]]="M","Male",IF( orders[[#This Row],[Customer Gender]]="F","Female",IF( orders[[#This Row],[Customer Gender]]="O","Other", "Unknown"))) -> Male
A8: TX500007 | B8: Sandals | C8: 1 | D8: 55.3 | E8: 55.3 | F8: 45658 | G8: 45659 | H8: F | I8: App | J8: 4 | K8: California | L8: Los Angeles County | M8: =orders[[#This Row],[Ship Date]]-orders[[#This Row],[Order Date]] -> 1 | N8: =WEEKNUM(orders[[#This Row],[Order Date]]) -> 1 | O8: =IF(orders[[#This Row],[Customer Gender]]="M","Male",IF( orders[[#This Row],[Customer Gender]]="F","Female",IF( orders[[#This Row],[Customer Gender]]="O","Other", "Unknown"))) -> Female
A9: TX500008 | B9: Jeans | C9: 2 | D9: 40.3 | E9: 80.6 | F9: 45658 | G9: 45659 | H9: M | I9: Target.com | J9: 5 | K9: California | L9: Los Angeles County | M9: =orders[[#This Row],[Ship Date]]-orders[[#This Row],[Order Date]] -> 1 | N9: =WEEKNUM(orders[[#This Row],[Order Date]]) -> 1 | O9: =IF(orders[[#This Row],[Customer Gender]]="M","Male",IF( orders[[#This Row],[Customer Gender]]="F","Female",IF( orders[[#This Row],[Customer Gender]]="O","Other", "Unknown"))) -> Male
A10: TX500009 | B10: Hoodies & Sweatshirts | C10: 11 | D10: 35.7 | E10: 392.7 | F10: 45658 | G10: 45659 | H10: F | I10: App | J10: 4 | K10: California | L10: Los Angeles County | M10: =orders[[#This Row],[Ship Date]]-orders[[#This Row],[Order Date]] -> 1 | N10: =WEEKNUM(orders[[#This Row],[Order Date]]) -> 1 | O10: =IF(orders[[#This Row],[Customer Gender]]="M","Male",IF( orders[[#This Row],[Customer Gender]]="F","Female",IF( orders[[#This Row],[Customer Gender]]="O","Other", "Unknown"))) -> Female
A11: TX500010 | B11: T-Shirts | C11: 7 | D11: 22.4 | E11: 156.8 | F11: 45658 | G11: 45661 | H11: M | I11: App | J11: 3 | K11: California | L11: Los Angeles County | M11: =orders[[#This Row],[Ship Date]]-orders[[#This Row],[Order Date]] -> 3 | N11: =WEEKNUM(orders[[#This Row],[Order Date]]) -> 1 | O11: =IF(orders[[#This Row],[Customer Gender]]="M","Male",IF( orders[[#This Row],[Customer Gender]]="F","Female",IF( orders[[#This Row],[Customer Gender]]="O","Other", "Unknown"))) -> Male
A12: TX500011 | B12: Sundresses | C12: 2 | D12: 54.4 | E12: 108.8 | F12: 45658 | G12: 45664 | H12: F | I12: App | J12: 4 | K12: California | L12: Los Angeles County | M12: =orders[[#This Row],[Ship Date]]-orders[[#This Row],[Order Date]] -> 6 | N12: =WEEKNUM(orders[[#This Row],[Order Date]]) -> 1 | O12: =IF(orders[[#This Row],[Customer Gender]]="M","Male",IF( orders[[#This Row],[Customer Gender]]="F","Female",IF( orders[[#This Row],[Customer Gender]]="O","Other", "Unknown"))) -> Female
A13: TX500012 | B13: Sundresses | C13: 2 | D13: 49 | E13: 98 | F13: 45658 | G13: 45660 | H13: F | I13: Target.com | J13: 3 | K13: California | L13: Los Angeles County | M13: =orders[[#This Row],[Ship Date]]-orders[[#This Row],[Order Date]] -> 2 | N13: =WEEKNUM(orders[[#This Row],[Order Date]]) -> 1 | O13: =IF(orders[[#This Row],[Customer Gender]]="M","Male",IF( orders[[#This Row],[Customer Gender]]="F","Female",IF( orders[[#This Row],[Customer Gender]]="O","Other", "Unknown"))) -> Female
A14: TX500013 | B14: Sandals | C14: 7 | D14: 118.6 | E14: 830.2 | F14: 45658 | G14: 45662 | H14: F | I14: Website | J14: 4 | K14: California | L14: Nevada County | M14: =orders[[#This Row],[Ship Date]]-orders[[#This Row],[Order Date]] -> 4 | N14: =WEEKNUM(orders[[#This Row],[Order Date]]) -> 1 | O14: =IF(orders[[#This Row],[Customer Gender]]="M","Male",IF( orders[[#This Row],[Customer Gender]]="F","Female",IF( orders[[#This Row],[Customer Gender]]="O","Other", "Unknown"))) -> Female
... A28: TX500027 | B28: Tank Tops | C28: 9 | D28: 38.7 | E28: 348.3 | F28: 45658 | G28: 45661 | H28: M | I28: Website | J28: 4 | K28: California | L28: Santa Barbara County | M28: =orders[[#This Row],[Ship Date]]-orders[[#This Row],[Order Date]] -> 3 | N28: =WEEKNUM(orders[[#This Row],[Order Date]]) -> 1 | O28: =IF(orders[[#This Row],[Customer Gender]]="M","Male",IF( orders[[#This Row],[Customer Gender]]="F","Female",IF( orders[[#This Row],[Customer Gender]]="O","Other", "Unknown"))) -> Male
A29: TX500028 | B29: Tote Bags | C29: 4 | D29: 57.2 | E29: 228.8 | F29: 45658 | G29: 45660 | I29: Website | J29: 5 | K29: California | L29: Santa Clara County | M29: =orders[[#This Row],[Ship Date]]-orders[[#This Row],[Order Date]] -> 2 | N29: =WEEKNUM(orders[[#This Row],[Order Date]]) -> 1 | O29: =IF(orders[[#This Row],[Customer Gender]]="M","Male",IF( orders[[#This Row],[Customer Gender]]="F","Female",IF( orders[[#This Row],[Customer Gender]]="O","Other", "Unknown"))) -> Unknown
A30: TX500029 | B30: Jeans | C30: 5 | D30: 50.9 | E30: 254.5 | F30: 45658 | G30: 45664 | I30: Website | J30: 5 | K30: California | L30: Tehama County | M30: =orders[[#This Row],[Ship Date]]-orders[[#This Row],[Order Date]] -> 6 | N30: =WEEKNUM(orders[[#This Row],[Order Date]]) -> 1 | O30: =IF(orders[[#This Row],[Customer Gender]]="M","Male",IF( orders[[#This Row],[Customer Gender]]="F","Female",IF( orders[[#This Row],[Customer Gender]]="O","Other", "Unknown"))) -> Unknown
A31: TX500030 | B31: Baseball Caps | C31: 7 | D31: 41 | E31: 287 | F31: 45658 | G31: 45662 | H31: F | I31: Website | J31: 4 | K31: California | L31: Ventura County | M31: =orders[[#This Row],[Ship Date]]-orders[[#This Row],[Order Date]] -> 4 | N31: =WEEKNUM(orders[[#This Row],[Order Date]]) -> 1 | O31: =IF(orders[[#This Row],[Customer Gender]]="M","Male",IF( orders[[#This Row],[Customer Gender]]="F","Female",IF( orders[[#This Row],[Customer Gender]]="O","Other", "Unknown"))) -> Female
A32: TX500031 | B32: T-Shirts | C32: 7 | D32: 19.1 | E32: 133.7 | F32: 45658 | G32: 45662 | H32: M | I32: App | J32: 5 | K32: California | L32: Calaveras County | M32: =orders[[#This Row],[Ship Date]]-orders[[#This Row],[Order Date]] -> 4 | N32: =WEEKNUM(orders[[#This Row],[Order Date]]) -> 1 | O32: =IF(orders[[#This Row],[Customer Gender]]="M","Male",IF( orders[[#This Row],[Customer Gender]]="F","Female",IF( orders[[#This Row],[Customer Gender]]="O","Other", "Unknown"))) -> Male
A33: TX500032 | B33: Sneakers | C33: 5 | D33: 166.1 | E33: 830.5 | F33: 45658 | G33: 45661 | H33: M | I33: App | J33: 4 | K33: California | L33: Inyo County | M33: =orders[[#This Row],[Ship Date]]-orders[[#This Row],[Order Date]] -> 3 | N33: =WEEKNUM(orders[[#This Row],[Order Date]]) -> 1 | O33: =IF(orders[[#This Row],[Customer Gender]]="M","Male",IF( orders[[#This Row],[Customer Gender]]="F","Female",IF( orders[[#This Row],[Customer Gender]]="O","Other", "Unknown"))) -> Male
A34: TX500033 | B34: Graphic Tees | C34: 3 | D34: 29.9 | E34: 89.7 | F34: 45658 | G34: 45659 | H34: M | I34: Instagram | J34: 4 | K34: California | L34: Los Angeles County | M34: =orders[[#This Row],[Ship Date]]-orders[[#This Row],[Order Date]] -> 1 | N34: =WEEKNUM(orders[[#This Row],[Order Date]]) -> 1 | O34: =IF(orders[[#This Row],[Customer Gender]]="M","Male",IF( orders[[#This Row],[Customer Gender]]="F","Female",IF( orders[[#This Row],[Customer Gender]]="O","Other", "Unknown"))) -> Male
A35: TX500034 | B35: Bikinis | C35: 6 | D35: 21.7 | E35: 130.2 | F35: 45658 | G35: 45660 | H35: O | I35: Target.com | J35: 5 | K35: California | L35: Los Angeles County | M35: =orders[[#This Row],[Ship Date]]-orders[[#This Row],[Order Date]] -> 2 | N35: =WEEKNUM(orders[[#This Row],[Order Date]]) -> 1 | O35: =IF(orders[[#This Row],[Customer Gender]]="M","Male",IF( orders[[#This Row],[Customer Gender]]="F","Female",IF( orders[[#This Row],[Customer Gender]]="O","Other", "Unknown"))) -> Other
A36: TX500035 | B36: Maxi Dresses | C36: 2 | D36: 32 | E36: 64 | F36: 45658 | G36: 45661 | H36: M | I36: App | J36: 5 | K36: California | L36: Los Angeles County | M36: =orders[[#This Row],[Ship Date]]-orders[[#This Row],[Order Date]] -> 3 | N36: =WEEKNUM(orders[[#This Row],[Order Date]]) -> 1 | O36: =IF(orders[[#This Row],[Customer Gender]]="M","Male",IF( orders[[#This Row],[Customer Gender]]="F","Female",IF( orders[[#This Row],[Customer Gender]]="O","Other", "Unknown"))) -> Male
A37: TX500036 | B37: T-Shirts | C37: 2 | D37: 15.8 | E37: 31.6 | F37: 45658 | G37: 45659 | H37: M | I37: Partner App | J37: 5 | K37: California | L37: Los Angeles County | M37: =orders[[#This Row],[Ship Date]]-orders[[#This Row],[Order Date]] -> 1 | N37: =WEEKNUM(orders[[#This Row],[Order Date]]) -> 1 | O37: =IF(orders[[#This Row],[Customer Gender]]="M","Male",IF( orders[[#This Row],[Customer Gender]]="F","Female",IF( orders[[#This Row],[Customer Gender]]="O","Other", "Unknown"))) -> Male
A38: TX500037 | B38: Sneakers | C38: 17 | D38: 203.1 | E38: 3452.7 | F38: 45658 | G38: 45662 | H38: M | I38: Instagram | J38: 3 | K38: California | L38: Los Angeles County | M38: =orders[[#This Row],[Ship Date]]-orders[[#This Row],[Order Date]] -> 4 | N38: =WEEKNUM(orders[[#This Row],[Order Date]]) -> 1 | O38: =IF(orders[[#This Row],[Customer Gender]]="M","Male",IF( orders[[#This Row],[Customer Gender]]="F","Female",IF( orders[[#This Row],[Customer Gender]]="O","Other", "Unknown"))) -> Male
A39: TX500038 | B39: Hoodies & Sweatshirts | C39: 13 | D39: 39 | E39: 507 | F39: 45658 | G39: 45664 | H39: M | I39: App | J39: 5 | K39: California | L39: Los Angeles County | M39: =orders[[#This Row],[Ship Date]]-orders[[#This Row],[Order Date]] -> 6 | N39: =WEEKNUM(orders[[#This Row],[Order Date]]) -> 1 | O39: =IF(orders[[#This Row],[Customer Gender]]="M","Male",IF( orders[[#This Row],[Customer Gender]]="F","Female",IF( orders[[#This Row],[Customer Gender]]="O","Other", "Unknown"))) -> Male
A40: TX500039 | B40: Bikinis | C40: 1 | D40: 26.5 | E40: 26.5 | F40: 45659 | G40: 45660 | H40: M | I40: Target.com | J40: 4 | K40: California | L40: Los Angeles County | M40: =orders[[#This Row],[Ship Date]]-orders[[#This Row],[Order Date]] -> 1 | N40: =WEEKNUM(orders[[#This Row],[Order Date]]) -> 1 | O40: =IF(orders[[#This Row],[Customer Gender]]="M","Male",IF( orders[[#This Row],[Customer Gender]]="F","Female",IF( orders[[#This Row],[Customer Gender]]="O","Other", "Unknown"))) -> Male
A41: TX500040 | B41: Sandals | C41: 1 | D41: 43.1 | E41: 43.1 | F41: 45659 | G41: 45660 | H41: F | I41: Target.com | J41: 3 | K41: California | L41: Los Angeles County | M41: =orders[[#This Row],[Ship Date]]-orders[[#This Row],[Order Date]] -> 1 | N41: =WEEKNUM(orders[[#This Row],[Order Date]]) -> 1 | O41: =IF(orders[[#This Row],[Customer Gender]]="M","Male",IF( orders[[#This Row],[Customer Gender]]="F","Female",IF( orders[[#This Row],[Customer Gender]]="O","Other", "Unknown"))) -> Female
A42: TX500041 | B42: Tank Tops | C42: 3 | D42: 139 | E42: 417 | F42: 45659 | G42: 45660 | H42: F | I42: Partner App | J42: 5 | K42: California | L42: Los Angeles County | M42: =orders[[#This Row],[Ship Date]]-orders[[#This Row],[Order Date]] -> 1 | N42: =WEEKNUM(orders[[#This Row],[Order Date]]) -> 1 | O42: =IF(orders[[#This Row],[Customer Gender]]="M","Male",IF( orders[[#This Row],[Customer Gender]]="F","Female",IF( orders[[#This Row],[Customer Gender]]="O","Other", "Unknown"))) -> Female
... A91: TX500090 | B91: Sneakers | C91: 1 | D91: 97.7 | E91: 97.7 | F91: 45661 | G91: 45664 | H91: F | I91: Website | J91: 4 | K91: California | L91: Los Angeles County | M91: =orders[[#This Row],[Ship Date]]-orders[[#This Row],[Order Date]] -> 3 | N91: =WEEKNUM(orders[[#This Row],[Order Date]]) -> 1 | O91: =IF(orders[[#This Row],[Customer Gender]]="M","Male",IF( orders[[#This Row],[Customer Gender]]="F","Female",IF( orders[[#This Row],[Customer Gender]]="O","Other", "Unknown"))) -> Female
A92: TX500091 | B92: Sundresses | C92: 5 | D92: 54.7 | E92: 273.5 | F92: 45661 | G92: 45664 | I92: App | J92: 5 | K92: California | L92: Riverside County | M92: =orders[[#This Row],[Ship Date]]-orders[[#This Row],[Order Date]] -> 3 | N92: =WEEKNUM(orders[[#This Row],[Order Date]]) -> 1 | O92: =IF(orders[[#This Row],[Customer Gender]]="M","Male",IF( orders[[#This Row],[Customer Gender]]="F","Female",IF( orders[[#This Row],[Customer Gender]]="O","Other", "Unknown"))) -> Unknown
A93: TX500092 | B93: Sneakers | C93: 6 | D93: 130.5 | E93: 783 | F93: 45661 | G93: 45663 | H93: F | I93: App | J93: 3 | K93: California | L93: Riverside County | M93: =orders[[#This Row],[Ship Date]]-orders[[#This Row],[Order Date]] -> 2 | N93: =WEEKNUM(orders[[#This Row],[Order Date]]) -> 1 | O93: =IF(orders[[#This Row],[Customer Gender]]="M","Male",IF( orders[[#This Row],[Customer Gender]]="F","Female",IF( orders[[#This Row],[Customer Gender]]="O","Other", "Unknown"))) -> Female
A94: TX500093 | B94: Maxi Dresses | C94: 2 | D94: 50.4 | E94: 100.8 | F94: 45661 | G94: 45663 | H94: M | I94: Target.com | J94: 5 | K94: California | L94: Sacramento County | M94: =orders[[#This Row],[Ship Date]]-orders[[#This Row],[Order Date]] -> 2 | N94: =WEEKNUM(orders[[#This Row],[Order Date]]) -> 1 | O94: =IF(orders[[#This Row],[Customer Gender]]="M","Male",IF( orders[[#This Row],[Customer Gender]]="F","Female",IF( orders[[#This Row],[Customer Gender]]="O","Other", "Unknown"))) -> Male
A95: TX500094 | B95: Jeans | C95: 13 | D95: 61.5 | E95: 799.5 | F95: 45661 | G95: 45662 | I95: Instagram | J95: 3 | K95: California | L95: Santa Clara County | M95: =orders[[#This Row],[Ship Date]]-orders[[#This Row],[Order Date]] -> 1 | N95: =WEEKNUM(orders[[#This Row],[Order Date]]) -> 1 | O95: =IF(orders[[#This Row],[Customer Gender]]="M","Male",IF( orders[[#This Row],[Customer Gender]]="F","Female",IF( orders[[#This Row],[Customer Gender]]="O","Other", "Unknown"))) -> Unknown
A96: TX500095 | B96: Sundresses | C96: 4 | D96: 30.1 | E96: 120.4 | F96: 45661 | G96: 45662 | H96: F | I96: App | J96: 5 | K96: California | L96: Alameda County | M96: =orders[[#This Row],[Ship Date]]-orders[[#This Row],[Order Date]] -> 1 | N96: =WEEKNUM(orders[[#This Row],[Order Date]]) -> 1 | O96: =IF(orders[[#This Row],[Customer Gender]]="M","Male",IF( orders[[#This Row],[Customer Gender]]="F","Female",IF( orders[[#This Row],[Customer Gender]]="O","Other", "Unknown"))) -> Female
A97: TX500096 | B97: Sneakers | C97: 5 | D97: 74.8 | E97: 374 | F97: 45661 | G97: 45662 | H97: F | I97: Website | J97: 4 | K97: California | L97: Contra Costa County | M97: =orders[[#This Row],[Ship Date]]-orders[[#This Row],[Order Date]] -> 1 | N97: =WEEKNUM(orders[[#This Row],[Order Date]]) -> 1 | O97: =IF(orders[[#This Row],[Customer Gender]]="M","Male",IF( orders[[#This Row],[Customer Gender]]="F","Female",IF( orders[[#This Row],[Customer Gender]]="O","Other", "Unknown"))) -> Female
A98: TX500097 | B98: Sunglasses | C98: 3 | D98: 64.9 | E98: 194.7 | F98: 45661 | G98: 45668 | H98: M | I98: App | J98: 4 | K98: California | L98: Fresno County | M98: =orders[[#This Row],[Ship Date]]-orders[[#This Row],[Order Date]] -> 7 | N98: =WEEKNUM(orders[[#This Row],[Order Date]]) -> 1 | O98: =IF(orders[[#This Row],[Customer Gender]]="M","Male",IF( orders[[#This Row],[Customer Gender]]="F","Female",IF( orders[[#This Row],[Customer Gender]]="O","Other", "Unknown"))) -> Male
A99: TX500098 | B99: Sundresses | C99: 2 | D99: 50.5 | E99: 101 | F99: 45661 | G99: 45663 | H99: M | I99: Website | J99: 4 | K99: California | L99: Kern County | M99: =orders[[#This Row],[Ship Date]]-orders[[#This Row],[Order Date]] -> 2 | N99: =WEEKNUM(orders[[#This Row],[Order Date]]) -> 1 | O99: =IF(orders[[#This Row],[Customer Gender]]="M","Male",IF( orders[[#This Row],[Customer Gender]]="F","Female",IF( orders[[#This Row],[Customer Gender]]="O","Other", "Unknown"))) -> Male
A100: TX500099 | B100: Maxi Dresses | C100: 7 | D100: 63 | E100: 441 | F100: 45661 | G100: 45664 | H100: M | I100: Instagram | J100: 5 | K100: California | L100: Los Angeles County | M100: =orders[[#This Row],[Ship Date]]-orders[[#This Row],[Order Date]] -> 3 | N100: =WEEKNUM(orders[[#This Row],[Order Date]]) -> 1 | O100: =IF(orders[[#This Row],[Customer Gender]]="M","Male",IF( orders[[#This Row],[Customer Gender]]="F","Female",IF( orders[[#This Row],[Customer Gender]]="O","Other", "Unknown"))) -> Male
A101: TX500100 | B101: Sneakers | C101: 3 | D101: 93.6 | E101: 280.8 | F101: 45661 | G101: 45674 | H101: F | I101: App | J101: 5 | K101: California | L101: Los Angeles County | M101: =orders[[#This Row],[Ship Date]]-orders[[#This Row],[Order Date]] -> 13 | N101: =WEEKNUM(orders[[#This Row],[Order Date]]) -> 1 | O101: =IF(orders[[#This Row],[Customer Gender]]="M","Male",IF( orders[[#This Row],[Customer Gender]]="F","Female",IF( orders[[#This Row],[Customer Gender]]="O","Other", "Unknown"))) -> Female
...

Sheet Dashboard

Sheet KPI
B3: Orders | C3: Quantity | D3: Amount | E3: Ratings | F3: Days
B4: =Pivot!A3 -> 2400 | C4: =Pivot!B3 -> 11997 | D4: =TEXT(Pivot!C3/1000,"$#,##0") -> $649,020 | E4: =TEXT(Pivot!D3,"#,##") -> 3,96 | F4: =SUBSTITUTE(TEXT(Pivot!E3,"#,##"),".",",") -> 2,34

Sheet Pivot
A2: Nombre de TX ID | B2: Somme de Quantity | C2: Somme de Amount | D2: Moyenne de Rating C | E2: Moyenne de Days to Deliver
A3: 2400 | B3: 11997 | C3: 649019.8 | D3: 3.9620833 | E3: 2.3425 | M3: State | N3: County | O3: Somme de Quantity | P3: Somme de Amount
M4: California | N4: Alameda County | O4: 579 | P4: 31885
M5: California | N5: Alpine County | O5: 1 | P5: 10.9
M6: California | N6: Amador County | O6: 9 | P6: 800.3
M7: California | N7: Butte County | O7: 35 | P7: 1062.6
A8: Row Labels | B8: Somme de Quantity | C8: Somme de Amount | M8: California | N8: Calaveras County | O8: 12 | P8: 326.2
A9: 1 | B9: 546 | C9: 32413.3 | M9: California | N9: Colusa County | O9: 4 | P9: 167.5
A10: 2 | B10: 905 | C10: 49563 | M10: California | N10: Contra Costa County | O10: 341 | P10: 16168.7
A11: 3 | B11: 796 | C11: 41700.4 | M11: California | N11: Del Norte County | O11: 13 | P11: 322.4
A12: 4 | B12: 913 | C12: 46782.6 | M12: California | N12: El Dorado County | O12: 31 | P12: 2092.8
A13: 5 | B13: 844 | C13: 42676.1 | M13: California | N13: Fresno County | O13: 279 | P13: 12662.5
A14: 6 | B14: 1202 | C14: 62910.7 | M14: California | N14: Glenn County | O14: 9 | P14: 343.2
A15: 7 | B15: 935 | C15: 50332.2 | M15: California | N15: Humboldt County | O15: 49 | P15: 2188.3
A16: 8 | B16: 1128 | C16: 58760.6 | M16: California | N16: Imperial County | O16: 59 | P16: 2661.6
A17: 9 | B17: 1007 | C17: 52017.3 | M17: California | N17: Inyo County | O17: 8 | P17: 887.5
A18: 10 | B18: 1128 | C18: 64915.7 | M18: California | N18: Kern County | O18: 222 | P18: 11354.2
A19: 11 | B19: 861 | C19: 45943.8 | M19: California | N19: Kings County | O19: 36 | P19: 1558.4
A20: 12 | B20: 944 | C20: 55077.9 | M20: California | N20: Lake County | O20: 30 | P20: 2223.9
A21: 13 | B21: 788 | C21: 45926.2 | M21: California | N21: Lassen County | O21: 1 | P21: 26.2
A22: Grand Total | B22: 11997 | C22: 649019.8 | M22: California | N22: Los Angeles County | O22: 3991 | P22: 215551.2
M23: California | N23: Madera County | O23: 45 | P23: 2687.4
M24: California | N24: Marin County | O24: 39 | P24: 1463.3
M25: California | N25: Mariposa County | O25: 6 | P25: 445.8
M26: California | N26: Mendocino County | O26: 9 | P26: 273.6
M27: California | N27: Merced County | O27: 60 | P27: 2690.4
A28: Row Labels | B28: Nombre de TX ID | E28: Somme de Quantity | F28: Column Labels | M28: California | N28: Modoc County | O28: 2 | P28: 28.4
A29: 1 | B29: 397 | E29: Row Labels | F29: Female | G29: Male | H29: Other | I29: Unknown | J29: Grand Total | M29: California | N29: Mono County | O29: 4 | P29: 204.8
A30: 2 | B30: 540 | E30: T-Shirts | F30: 744 | G30: 713 | H30: 90 | I30: 98 | J30: 1645 | M30: California | N30: Monterey County | O30: 31 | P30: 1607.9
A31: 3 | B31: 375 | E31: Jeans | F31: 716 | G31: 598 | H31: 18 | I31: 214 | J31: 1546 | M31: California | N31: Napa County | O31: 88 | P31: 6444.9
A32: 4 | B32: 246 | E32: Sneakers | F32: 627 | G32: 393 | H32: 29 | I32: 137 | J32: 1186 | M32: California | N32: Nevada County | O32: 25 | P32: 1809.3
A33: 5 | B33: 195 | E33: Tank Tops | F33: 568 | G33: 306 | H33: 22 | I33: 16 | J33: 912 | M33: California | N33: Orange County | O33: 178 | P33: 9680.4
A34: 6 to 15 | B34: 539 | E34: Bikinis | F34: 482 | G34: 295 | H34: 8 | I34: 22 | J34: 807 | M34: California | N34: Placer County | O34: 141 | P34: 9414.8
A35: Over 15 | B35: 108 | E35: Shorts | F35: 428 | G35: 293 | I35: 24 | J35: 745 | M35: California | N35: Plumas County | O35: 6 | P35: 206.1
A36: Grand Total | B36: 2400 | E36: Sundresses | F36: 445 | G36: 202 | H36: 14 | I36: 39 | J36: 700 | M36: California | N36: Riverside County | O36: 178 | P36: 7691.3
E37: Graphic Tees | F37: 431 | G37: 187 | H37: 14 | I37: 15 | J37: 647 | M37: California | N37: Sacramento County | O37: 699 | P37: 37784.9
E38: Hoodies & Sweatshirts | F38: 264 | G38: 318 | H38: 15 | I38: 9 | J38: 606 | M38: California | N38: San Benito County | O38: 23 | P38: 1129.7
E39: Sandals | F39: 296 | G39: 275 | H39: 9 | I39: 23 | J39: 603 | M39: California | N39: San Bernardino County | O39: 356 | P39: 20988.9
A40: Row Labels | B40: Somme de Quantity | E40: Grand Total | F40: 5001 | G40: 3580 | H40: 219 | I40: 597 | J40: 9397 | M40: California | N40: San Diego County | O40: 1768 | P40: 98367.1
A41: Female | B41: 6272 | M41: California | N41: San Francisco | O41: 307 | P41: 21911.9
...

Sheet pivot1
A1: Somme de Amount | B1: Étiquettes de colonnes
A2: Étiquettes de lignes | B2: Female | C2: Male | D2: Other | E2: Unknown | F2: Total général
A3: App | B3: 0.18961825 | C3: 0.12262322 | D3: 0.010605378 | E3: 0.030599221 | F3: 0.35344607
A4: Instagram | B4: 0.050283982 | C4: 0.043060782 | D4: 0.0015320026 | E4: 0.017794989 | F4: 0.11267176
A5: Partner App | B5: 0.06349606 | C5: 0.04607163 | D5: 0.0023062471 | E5: 0.0038927934 | F5: 0.11576673
A6: Target.com | B6: 0.096337893 | C6: 0.067920116 | D6: 0.0054979833 | E6: 0.012933041 | F6: 0.18268903
A7: Website | B7: 0.12522099 | C7: 0.09149274 | D7: 0.0063042761 | E7: 0.012408404 | F7: 0.23542641
A8: Total général | B8: 0.52495717 | C8: 0.37116849 | D8: 0.026245886 | E8: 0.077628448 | F8: 1
B12: =pivot1!B2 -> Female | C12: =pivot1!C2 -> Male | D12: =pivot1!D2 -> Other | E12: =pivot1!E2 -> Unknown
A13: =pivot1!A3 -> App | B13: =pivot1!B3 -> 0.18961825 | C13: =pivot1!C3 -> 0.12262322 | D13: =pivot1!D3 -> 0.010605378 | E13: =pivot1!E3 -> 0.030599221
A14: =pivot1!A4 -> Instagram | B14: =pivot1!B4 -> 0.050283982 | C14: =pivot1!C4 -> 0.043060782 | D14: =pivot1!D4 -> 0.0015320026 | E14: =pivot1!E4 -> 0.017794989
A15: =pivot1!A5 -> Partner App | B15: =pivot1!B5 -> 0.06349606 | C15: =pivot1!C5 -> 0.04607163 | D15: =pivot1!D5 -> 0.0023062471 | E15: =pivot1!E5 -> 0.0038927934
A16: =pivot1!A6 -> Target.com | B16: =pivot1!B6 -> 0.096337893 | C16: =pivot1!C6 -> 0.067920116 | D16: =pivot1!D6 -> 0.0054979833 | E16: =pivot1!E6 -> 0.012933041
A17: =pivot1!A7 -> Website | B17: =pivot1!B7 -> 0.12522099 | C17: =pivot1!C7 -> 0.09149274 | D17: =pivot1!D7 -> 0.0063042761 | E17: =pivot1!E7 -> 0.012408404
A22: Row Labels | B22: Somme de Amount
A23: janv | B23: 206358.8
A24: févr | B24: 227221.8
A25: mars | B25: 215439.2
